Workbook

Sheet sheet1
A1: Financial Line Item | B1: SMC 2023 | C1: SMC 2024 | D1: SMC 2025 | E1: Thatta Cement 2025
A2: STATEMENT OF PROFIT OR LOSS
A3: Revenue - net | B3: 1432034758 | C3: 1262480359 | D3: 1652008725 | E3: 7566414000
A4: Cost of sales | B4: 1110758758 | C4: 1002413228 | D4: 1395658868 | E4: 5415712000
A5: Gross profit | B5: 321276000 | C5: 260067131 | D5: 256349857 | E5: 2150702000
A6: Distribution and selling expenses | B6: 2325510 | C6: 2260126 | D6: 9311897 | E6: 45877000
A7: Administrative and general expenses | B7: 45320886 | C7: 49268320 | D7: 57665328 | E7: 151889000
A8: Other operating expenses | B8: 35340012 | C8: 18390427 | D8: 6484478 | E8: 269726000
A9: Other income | B9: 9556857 | C9: 8724897 | D9: 6423943 | E9: 1999167000
A10: Operating profit (EBIT) | B10: 273629604 | C10: 208538685 | D10: 189372632 | E10: 1683210000
A11: Finance costs | B11: 40873518 | C11: 52225884 | D11: 37315642 | E11: 43032000
A12: Levies | B12: 0 | C12: 0 | D12: 10920101 | E12: 0
A13: Profit before taxation | B13: 206972931 | C13: 146647271 | D13: 141076354 | E13: 3639345000
A14: Taxation | B14: 73602474 | C14: 35041646 | D14: 38362713 | E14: 1082762000
A15: Profit after taxation | B15: 133370457 | C15: 111605625 | D15: 102713641 | E15: 2556583000
A16: STATEMENT OF FINANCIAL POSITION
A17: Non-current assets
A18: Property, plant and equipment | B18: 296802818 | C18: 276007874 | D18: 268353782 | E18: 3425606000
A19: Right-of-use assets | B19: 0 | C19: 4085953 | D19: 3064465 | E19: 0
A20: Intangible assets | B20: 203270 | C20: 182942 | D20: 162222 | E20: 1755000
A21: Long-term investments | B21: 0 | C21: 0 | D21: 0 | E21: 936658000
A22: Long-term loans and advances | B22: 758006 | C22: 493546 | D22: 96134600 | E22: 0
A23: Long-term deposits | B23: 23500 | C23: 23500 | D23: 23500 | E23: 5125000
A24: Deferred taxation - net | B24: 49303276 | C24: 43420333 | D24: 46141187 | E24: 0
A25: Total Non-current assets | B25: 347090870 | C25: 324214148 | D25: 413879756 | E25: 4369144000
A26: Current assets
A27: Stores, spares and loose tools | B27: 13462701 | C27: 15904146 | D27: 19408559 | E27: 358337000
A28: Stock-in-trade | B28: 25495768 | C28: 29610514 | D28: 21179019 | E28: 62238000
A29: Trade debts | B29: 330208117 | C29: 347516161 | D29: 379613239 | E29: 166366000
A30: Loans and advances | B30: 3363051 | C30: 7554860 | D30: 20250726 | E30: 162050000
A31: Prepayments, deposits and other receivables | B31: 2701209 | C31: 3041634 | D31: 5333269 | E31: 327227000
A32: Short-term investments | B32: 0 | C32: 0 | D32: 0 | E32: 0
A33: Taxation net / Tax refunds | B33: 6229916 | C33: 30989741 | D33: 80724361 | E33: 0
A34: Cash and bank balances | B34: 16431416 | C34: 46796567 | D34: 52709351 | E34: 4069729000
A35: Total Current assets | B35: 397892178 | C35: 481413623 | D35: 579218524 | E35: 5145947000
A36: TOTAL ASSETS | B36: 744983048 | C36: 805627771 | D36: 993098280 | E36: 9515091000
A37: Share capital and reserves
A38: Issued, subscribed and paid up capital | B38: 250000000 | C38: 250000000 | D38: 250000000 | E38: 847181000
A39: Share premium | B39: 14728576 | C39: 14728576 | D39: 14728576 | E39: 0
A40: Revenue reserve - Accumulated profit | B40: 9566086 | C40: 117665053 | D40: 179531522 | E40: 5851270000
...

Sheet Sheet2
A1: Ratio Category & Name | B1: SMC 2023 | C1: SMC 2024 | D1: SMC 2025 | E1: Thatta Cement 2025
A2: 1. Liquidity Ratios
A3: Current Ratio | B3: =sheet1!B35 / sheet1!B59 -> 1.0886467 | C3: =sheet1!C35 / sheet1!C59 -> 1.4288116 | D3: =sheet1!D35 / sheet1!D59 -> 1.3824841 | E3: =sheet1!E35 / sheet1!E59 -> 2.4128292
A4: Acid Test (Quick) Ratio | B4: =(sheet1!B35 - sheet1!B28) / sheet1!B59 -> 1.0188894 | C4: =(sheet1!C35 - sheet1!C28) / sheet1!C59 -> 1.340929 | D4: =(sheet1!D35 - sheet1!D28) / sheet1!D59 -> 1.3319338 | E4: =(sheet1!E35 - sheet1!E28) / sheet1!E59 -> 2.3836471
A5: 2. Solvency Ratios
A6: Total Debt to Equity | B6: =sheet1!B60 / sheet1!B41 -> 1.7159954 | C6: =sheet1!C60 / sheet1!C41 -> 1.1068023 | D6: =sheet1!D60 / sheet1!D41 -> 1.2353983 | E6: =sheet1!E60 / sheet1!E41 -> 0.42049124
A7: Total Debt to Total Asset | B7: =sheet1!B60 / sheet1!B36 -> 0.63181087 | C7: =sheet1!C60 / sheet1!C36 -> 0.52534701 | D7: =sheet1!D60 / sheet1!D36 -> 0.55265243 | E7: =sheet1!E60 / sheet1!E36 -> 0.29601819
A8: LT Debt to Total Capital | B8: =sheet1!B43 / (sheet1!B43 + sheet1!B41) -> 0.25235654 | C8: =sheet1!C43 / (sheet1!C43 + sheet1!C41) -> 0.13426469 | D8: =sheet1!D43 / (sheet1!D43 + sheet1!D41) -> 0.17970868 | E8: =sheet1!E43 / (sheet1!E43 + sheet1!E41) -> 0
A9: 3. Coverage Ratios
A10: Times Interest Earned | B10: =sheet1!B10 / sheet1!B11 -> 6.694545 | C10: =sheet1!C10 / sheet1!C11 -> 3.993014 | D10: =sheet1!D10 / sheet1!D11 -> 5.0748861 | E10: =sheet1!E10 / sheet1!E11 -> 39.11531
A11: 4. Activity Ratios
A12: Receivable Turnover | B12: =sheet1!B3 / sheet1!B29 -> 4.3367643 | C12: =sheet1!C3 / sheet1!C29 -> 3.6328681 | D12: =sheet1!D3 / sheet1!D29 -> 4.3518206 | E12: =sheet1!E3 / sheet1!E29 -> 45.480531
A13: Average Collection Period | B13: =365 / B12 -> 84.164132 | C13: =365 / C12 -> 100.47158 | D13: =365 / D12 -> 83.872942 | E13: =365 / E12 -> 8.025412
A14: Payable Turnover | B14: =sheet1!B4 / sheet1!B50 -> 5.115971 | C14: =sheet1!C4 / sheet1!C50 -> 5.2303911 | D14: =sheet1!D4 / sheet1!D50 -> 4.5924753 | E14: =sheet1!E4 / sheet1!E50 -> 4.0141957
A15: PTO in days | B15: =365 / B14 -> 71.345205 | C15: =365 / C14 -> 69.784457 | D15: =365 / D14 -> 79.477836 | E15: =365 / E14 -> 90.927306
A16: Inventory Turnover | B16: =sheet1!B4 / sheet1!B28 -> 43.566397 | C16: =sheet1!C4 / sheet1!C28 -> 33.853287 | D16: =sheet1!D4 / sheet1!D28 -> 65.898183 | E16: =sheet1!E4 / sheet1!E28 -> 87.016164
A17: ITO in days | B17: =365 / B16 -> 8.3780166 | C17: =365 / C16 -> 10.781819 | D17: =365 / D16 -> 5.5388477 | E17: =365 / E16 -> 4.194623
A18: Operating Cycle | B18: =B17 + B13 -> 92.542149 | C18: =C17 + C13 -> 111.2534 | D18: =D17 + D13 -> 89.41179 | E18: =E17 + E13 -> 12.220035
A19: Cash Cycle | B19: =B18 - B15 -> 21.196944 | C19: =C18 - C15 -> 41.468944 | D19: =D18 - D15 -> 9.933954 | E19: =E18 - E15 -> -78.707271
A20: Total Asset Turnover | B20: =sheet1!B3 / sheet1!B36 -> 1.922238 | C20: =sheet1!C3 / sheet1!C36 -> 1.5670765 | D20: =sheet1!D3 / sheet1!D36 -> 1.6634897 | E20: =sheet1!E3 / sheet1!E36 -> 0.79520143
A21: 5. Profitability Ratios
A22: Gross Profit Margin | B22: =sheet1!B5 / sheet1!B3 -> 0.2243493 | C22: =sheet1!C5 / sheet1!C3 -> 0.20599697 | D22: =sheet1!D5 / sheet1!D3 -> 0.15517464 | E22: =sheet1!E5 / sheet1!E3 -> 0.28424324
A23: Net Profit Margin | B23: =sheet1!B15 / sheet1!B3 -> 0.093133533 | C23: =sheet1!C15 / sheet1!C3 -> 0.08840187 | D23: =sheet1!D15 / sheet1!D3 -> 0.062174999 | E23: =sheet1!E15 / sheet1!E3 -> 0.33788569
A24: Return on Investment (ROA) | B24: =sheet1!B15 / sheet1!B36 -> 0.17902482 | C24: =sheet1!C15 / sheet1!C36 -> 0.13853249 | D24: =sheet1!D15 / sheet1!D36 -> 0.10342747 | E24: =sheet1!E15 / sheet1!E36 -> 0.26868718
A25: Return on Equity (ROE) | B25: =sheet1!B15 / sheet1!B41 -> 0.4862306 | C25: =sheet1!C15 / sheet1!C41 -> 0.29186058 | D25: =sheet1!D15 / sheet1!D41 -> 0.23120159 | E25: =sheet1!E15 / sheet1!E41 -> 0.38166779

Sheet Sheet3
A1: Financial Line Item | B1: Vertical SMC 2023 | C1: Vertical SMC 2024 | D1: Vertical SMC 2025 | G1: Index SMC 2023 | H1: Index SMC 2024 | I1: Index SMC 2025
A2: STATEMENT OF PROFIT OR LOSS
A3: Revenue - net | B3: =sheet1!B3/sheet1!B$3 -> 1 | C3: =sheet1!C3/sheet1!C$3 -> 1 | D3: =sheet1!D3/sheet1!D$3 -> 1 | G3: =sheet1!B3/sheet1!$B3 -> 1 | H3: =sheet1!C3/sheet1!$B3 -> 0.88159896 | I3: =sheet1!D3/sheet1!$B3 -> 1.1536094
A4: Cost of sales | B4: =sheet1!B4/sheet1!B$3 -> 0.7756507 | C4: =sheet1!C4/sheet1!C$3 -> 0.79400303 | D4: =sheet1!D4/sheet1!D$3 -> 0.84482536 | G4: =sheet1!B4/sheet1!$B4 -> 1 | H4: =sheet1!C4/sheet1!$B4 -> 0.90245809 | I4: =sheet1!D4/sheet1!$B4 -> 1.2564914
A5: Gross profit | B5: =sheet1!B5/sheet1!B$3 -> 0.2243493 | C5: =sheet1!C5/sheet1!C$3 -> 0.20599697 | D5: =sheet1!D5/sheet1!D$3 -> 0.15517464 | G5: =sheet1!B5/sheet1!$B5 -> 1 | H5: =sheet1!C5/sheet1!$B5 -> 0.80948197 | I5: =sheet1!D5/sheet1!$B5 -> 0.79791163
A6: Distribution and selling expenses | B6: =sheet1!B6/sheet1!B$3 -> 0.0016239201 | C6: =sheet1!C6/sheet1!C$3 -> 0.0017902267 | D6: =sheet1!D6/sheet1!D$3 -> 0.0056367118 | G6: =sheet1!B6/sheet1!$B6 -> 1 | H6: =sheet1!C6/sheet1!$B6 -> 0.97188402 | I6: =sheet1!D6/sheet1!$B6 -> 4.0042386
A7: Administrative and general expenses | B7: =sheet1!B7/sheet1!B$3 -> 0.031647895 | C7: =sheet1!C7/sheet1!C$3 -> 0.039025019 | D7: =sheet1!D7/sheet1!D$3 -> 0.034906189 | G7: =sheet1!B7/sheet1!$B7 -> 1 | H7: =sheet1!C7/sheet1!$B7 -> 1.0870997 | I7: =sheet1!D7/sheet1!$B7 -> 1.2723787
A8: Other operating expenses | B8: =sheet1!B8/sheet1!B$3 -> 0.02467818 | C8: =sheet1!C8/sheet1!C$3 -> 0.014566901 | D8: =sheet1!D8/sheet1!D$3 -> 0.0039252081 | G8: =sheet1!B8/sheet1!$B8 -> 1 | H8: =sheet1!C8/sheet1!$B8 -> 0.52038542 | I8: =sheet1!D8/sheet1!$B8 -> 0.18348828
A9: Other income | B9: =sheet1!B9/sheet1!B$3 -> 0.0066736208 | C9: =sheet1!C9/sheet1!C$3 -> 0.006910917 | D9: =sheet1!D9/sheet1!D$3 -> 0.0038885648 | G9: =sheet1!B9/sheet1!$B9 -> 1 | H9: =sheet1!C9/sheet1!$B9 -> 0.91294628 | I9: =sheet1!D9/sheet1!$B9 -> 0.67218156
A10: Operating profit (EBIT) | B10: =sheet1!B10/sheet1!B$3 -> 0.19107749 | C10: =sheet1!C10/sheet1!C$3 -> 0.16518173 | D10: =sheet1!D10/sheet1!D$3 -> 0.11463174 | G10: =sheet1!B10/sheet1!$B10 -> 1 | H10: =sheet1!C10/sheet1!$B10 -> 0.76212033 | I10: =sheet1!D10/sheet1!$B10 -> 0.69207655
A11: Finance costs | B11: =sheet1!B11/sheet1!B$3 -> 0.028542267 | C11: =sheet1!C11/sheet1!C$3 -> 0.04136768 | D11: =sheet1!D11/sheet1!D$3 -> 0.022588042 | G11: =sheet1!B11/sheet1!$B11 -> 1 | H11: =sheet1!C11/sheet1!$B11 -> 1.2777438 | I11: =sheet1!D11/sheet1!$B11 -> 0.91295401
A12: Levies | B12: =sheet1!B12/sheet1!B$3 -> 0 | C12: =sheet1!C12/sheet1!C$3 -> 0 | D12: =sheet1!D12/sheet1!D$3 -> 0.0066101957
A13: Profit before taxation | B13: =sheet1!B13/sheet1!B$3 -> 0.14453066 | C13: =sheet1!C13/sheet1!C$3 -> 0.11615806 | D13: =sheet1!D13/sheet1!D$3 -> 0.085396858 | G13: =sheet1!B13/sheet1!$B13 -> 1 | H13: =sheet1!C13/sheet1!$B13 -> 0.70853358 | I13: =sheet1!D13/sheet1!$B13 -> 0.68161741
A14: Taxation | B14: =sheet1!B14/sheet1!B$3 -> 0.051397128 | C14: =sheet1!C14/sheet1!C$3 -> 0.027756191 | D14: =sheet1!D14/sheet1!D$3 -> 0.023221859 | G14: =sheet1!B14/sheet1!$B14 -> 1 | H14: =sheet1!C14/sheet1!$B14 -> 0.47609332 | I14: =sheet1!D14/sheet1!$B14 -> 0.52121499
A15: Profit after taxation | B15: =sheet1!B15/sheet1!B$3 -> 0.093133533 | C15: =sheet1!C15/sheet1!C$3 -> 0.08840187 | D15: =sheet1!D15/sheet1!D$3 -> 0.062174999 | G15: =sheet1!B15/sheet1!$B15 -> 1 | H15: =sheet1!C15/sheet1!$B15 -> 0.8368092 | I15: =sheet1!D15/sheet1!$B15 -> 0.77013788
A16: STATEMENT OF FINANCIAL POSITION
A17: Non-current assets
A18: Property, plant and equipment | B18: =sheet1!B18/sheet1!B$36 -> 0.39840211 | C18: =sheet1!C18/sheet1!C$36 -> 0.34259975 | D18: =sheet1!D18/sheet1!D$36 -> 0.27021876 | G18: =sheet1!B18/sheet1!$B18 -> 1 | H18: =sheet1!C18/sheet1!$B18 -> 0.92993684 | I18: =sheet1!D18/sheet1!$B18 -> 0.90414836
A19: Right-of-use assets | B19: =sheet1!B19/sheet1!B$36 -> 0 | C19: =sheet1!C19/sheet1!C$36 -> 0.0050717628 | D19: =sheet1!D19/sheet1!D$36 -> 0.0030857621
A20: Intangible assets | B20: =sheet1!B20/sheet1!B$36 -> 0.00027285185 | C20: =sheet1!C20/sheet1!C$36 -> 0.00022708006 | D20: =sheet1!D20/sheet1!D$36 -> 0.00016334939 | G20: =sheet1!B20/sheet1!$B20 -> 1 | H20: =sheet1!C20/sheet1!$B20 -> 0.89999508 | I20: =sheet1!D20/sheet1!$B20 -> 0.79806169
A21: Long-term investments | B21: =sheet1!B21/sheet1!B$36 -> 0 | C21: =sheet1!C21/sheet1!C$36 -> 0 | D21: =sheet1!D21/sheet1!D$36 -> 0
A22: Long-term loans and advances | B22: =sheet1!B22/sheet1!B$36 -> 0.0010174809 | C22: =sheet1!C22/sheet1!C$36 -> 0.00061262287 | D22: =sheet1!D22/sheet1!D$36 -> 0.096802705 | G22: =sheet1!B22/sheet1!$B22 -> 1 | H22: =sheet1!C22/sheet1!$B22 -> 0.65111094 | I22: =sheet1!D22/sheet1!$B22 -> 126.82565
A23: Long-term deposits | B23: =sheet1!B23/sheet1!B$36 -> 3.1544342e-05 | C23: =sheet1!C23/sheet1!C$36 -> 2.9169799e-05 | D23: =sheet1!D23/sheet1!D$36 -> 2.3663318e-05
A24: Deferred taxation - net | B24: =sheet1!B24/sheet1!B$36 -> 0.0661804 | C24: =sheet1!C24/sheet1!C$36 -> 0.053896271 | D24: =sheet1!D24/sheet1!D$36 -> 0.046461854 | G24: =sheet1!B24/sheet1!$B24 -> 1 | H24: =sheet1!C24/sheet1!$B24 -> 0.88067846 | I24: =sheet1!D24/sheet1!$B24 -> 0.93586453
A25: Total Non-current assets | B25: =sheet1!B25/sheet1!B$36 -> 0.46590439 | C25: =sheet1!C25/sheet1!C$36 -> 0.40243666 | D25: =sheet1!D25/sheet1!D$36 -> 0.41675609 | G25: =sheet1!B25/sheet1!$B25 -> 1 | H25: =sheet1!C25/sheet1!$B25 -> 0.93409011 | I25: =sheet1!D25/sheet1!$B25 -> 1.1924248
A26: Current assets
A27: Stores, spares and loose tools | B27: =sheet1!B27/sheet1!B$36 -> 0.018071151 | C27: =sheet1!C27/sheet1!C$36 -> 0.019741308 | D27: =sheet1!D27/sheet1!D$36 -> 0.019543442 | G27: =sheet1!B27/sheet1!$B27 -> 1 | H27: =sheet1!C27/sheet1!$B27 -> 1.1813488 | I27: =sheet1!D27/sheet1!$B27 -> 1.4416542
A28: Stock-in-trade | B28: =sheet1!B28/sheet1!B$36 -> 0.034223286 | C28: =sheet1!C28/sheet1!C$36 -> 0.036754585 | D28: =sheet1!D28/sheet1!D$36 -> 0.021326207 | G28: =sheet1!B28/sheet1!$B28 -> 1 | H28: =sheet1!C28/sheet1!$B28 -> 1.1613894 | I28: =sheet1!D28/sheet1!$B28 -> 0.83068763
A29: Trade debts | B29: =sheet1!B29/sheet1!B$36 -> 0.44324246 | C29: =sheet1!C29/sheet1!C$36 -> 0.4313607 | D29: =sheet1!D29/sheet1!D$36 -> 0.38225143 | G29: =sheet1!B29/sheet1!$B29 -> 1 | H29: =sheet1!C29/sheet1!$B29 -> 1.0524156 | I29: =sheet1!D29/sheet1!$B29 -> 1.1496181
A30: Loans and advances | B30: =sheet1!B30/sheet1!B$36 -> 0.0045142651 | C30: =sheet1!C30/sheet1!C$36 -> 0.0093776062 | D30: =sheet1!D30/sheet1!D$36 -> 0.020391462 | G30: =sheet1!B30/sheet1!$B30 -> 1 | H30: =sheet1!C30/sheet1!$B30 -> 2.2464304 | I30: =sheet1!D30/sheet1!$B30 -> 6.021534
A31: Prepayments, deposits and other receivables | B31: =sheet1!B31/sheet1!B$36 -> 0.0036258664 | C31: =sheet1!C31/sheet1!C$36 -> 0.0037754831 | D31: =sheet1!D31/sheet1!D$36 -> 0.0053703335 | G31: =sheet1!B31/sheet1!$B31 -> 1 | H31: =sheet1!C31/sheet1!$B31 -> 1.1260269 | I31: =sheet1!D31/sheet1!$B31 -> 1.9744007
A32: Short-term investments | B32: =sheet1!B32/sheet1!B$36 -> 0 | C32: =sheet1!C32/sheet1!C$36 -> 0 | D32: =sheet1!D32/sheet1!D$36 -> 0
A33: Taxation net / Tax refunds | B33: =sheet1!B33/sheet1!B$36 -> 0.0083624936 | C33: =sheet1!C33/sheet1!C$36 -> 0.038466575 | D33: =sheet1!D33/sheet1!D$36 -> 0.08128537 | G33: =sheet1!B33/sheet1!$B33 -> 1 | H33: =sheet1!C33/sheet1!$B33 -> 4.9743433 | I33: =sheet1!D33/sheet1!$B33 -> 12.957536
A34: Cash and bank balances | B34: =sheet1!B34/sheet1!B$36 -> 0.022056094 | C34: =sheet1!C34/sheet1!C$36 -> 0.058087083 | D34: =sheet1!D34/sheet1!D$36 -> 0.053075664 | G34: =sheet1!B34/sheet1!$B34 -> 1 | H34: =sheet1!C34/sheet1!$B34 -> 2.8479936 | I34: =sheet1!D34/sheet1!$B34 -> 3.2078398
A35: Total Current assets | B35: =sheet1!B35/sheet1!B$36 -> 0.53409561 | C35: =sheet1!C35/sheet1!C$36 -> 0.59756334 | D35: =sheet1!D35/sheet1!D$36 -> 0.58324391 | G35: =sheet1!B35/sheet1!$B35 -> 1 | H35: =sheet1!C35/sheet1!$B35 -> 1.2099097 | I35: =sheet1!D35/sheet1!$B35 -> 1.4557173
A36: TOTAL ASSETS | B36: =sheet1!B36/sheet1!B$36 -> 1 | C36: =sheet1!C36/sheet1!C$36 -> 1 | D36: =sheet1!D36/sheet1!D$36 -> 1 | G36: =sheet1!B36/sheet1!$B36 -> 1 | H36: =sheet1!C36/sheet1!$B36 -> 1.0814042 | I36: =sheet1!D36/sheet1!$B36 -> 1.3330482
A37: Share capital and reserves
A38: Issued, subscribed and paid up capital | B38: =sheet1!B38/sheet1!B$61 -> 0.33557811 | C38: =sheet1!C38/sheet1!C$61 -> 0.31031701 | D38: =sheet1!D38/sheet1!D$61 -> 0.25173742 | G38: =sheet1!B38/sheet1!$B38 -> 1 | H38: =sheet1!C38/sheet1!$B38 -> 1 | I38: =sheet1!D38/sheet1!$B38 -> 1
A39: Share premium | B39: =sheet1!B39/sheet1!B$61 -> 0.019770351 | C39: =sheet1!C39/sheet1!C$61 -> 0.018282111 | D39: =sheet1!D39/sheet1!D$61 -> 0.014830935 | G39: =sheet1!B39/sheet1!$B39 -> 1 | H39: =sheet1!C39/sheet1!$B39 -> 1 | I39: =sheet1!D39/sheet1!$B39 -> 1
A40: Revenue reserve - Accumulated profit | B40: =sheet1!B40/sheet1!B$61 -> 0.012840676 | C40: =sheet1!C40/sheet1!C$61 -> 0.14605387 | D40: =sheet1!D40/sheet1!D$61 -> 0.18077921 | G40: =sheet1!B40/sheet1!$B40 -> 1 | H40: =sheet1!C40/sheet1!$B40 -> 12.300229 | I40: =sheet1!D40/sheet1!$B40 -> 18.7675
...

Sheet Sheet4
A2: Date | B2: SMC Price | C2: SMC Return (%) | D2: Thatta Price | E2: Thatta Return (%) | G2: SMC Dev (R-Mean) | H2: SMC Sq Dev | I2: Thatta Dev (R-Mean) | J2: Thatta Sq Dev | L2: Metric | M2: SMC | N2: Thatta Cement
A3: 46150 | B3: 41.8 | C3: 0.0175 | D3: 55.75 | E3: -0.015 | G3: =C3 - $M$4 -> 0.018241538 | H3: =G3^2 -> 0.00033275373 | I3: =E3 - $N$4 -> -0.012838462 | J3: =I3^2 -> 0.00016482609 | L3: Count (n) | M3: =COUNT(C3:C67) -> 65 | N3: =COUNT(E3:E67) -> 65
A4: 46149 | B4: 41.08 | C4: 0.0146 | D4: 56.6 | E4: 0.022 | G4: =C4 - $M$4 -> 0.015341538 | H4: =G4^2 -> 0.0002353628 | I4: =E4 - $N$4 -> 0.024161538 | J4: =I4^2 -> 0.00058377994 | L4: Average Return (Mean) | M4: =AVERAGE(C3:C67) -> -0.00074153846 | N4: =AVERAGE(E3:E67) -> -0.0021615385
A5: 46148 | B5: 40.49 | C5: 0.0503 | D5: 55.38 | E5: 0.0402 | G5: =C5 - $M$4 -> 0.051041538 | H5: =G5^2 -> 0.0026052386 | I5: =E5 - $N$4 -> 0.042361538 | J5: =I5^2 -> 0.0017944999 | L5: Sum of Sq Dev | M5: =SUM(H3:H67) -> 0.089588258 | N5: =SUM(J3:J67) -> 0.086095214
A6: 46147 | B6: 38.55 | C6: -0.0163 | D6: 53.24 | E6: -0.0088 | G6: =C6 - $M$4 -> -0.015558462 | H6: =G6^2 -> 0.00024206573 | I6: =E6 - $N$4 -> -0.0066384615 | J6: =I6^2 -> 4.4069172e-05 | L6: Variance (Manual) | M6: =M5/(M3-1) -> 0.0013998165 | N6: =N5/(N3-1) -> 0.0013452377
A7: 46146 | B7: 39.19 | C7: 0.0095 | D7: 53.71 | E7: 0.0081 | G7: =C7 - $M$4 -> 0.010241538 | H7: =G7^2 -> 0.00010488911 | I7: =E7 - $N$4 -> 0.010261538 | J7: =I7^2 -> 0.00010529917 | L7: Standard Deviation (Manual) | M7: =SQRT(M6) -> 0.037414122 | N7: =SQRT(N6) -> 0.036677482
A8: 46142 | B8: 38.82 | C8: 0.0128 | D8: 53.28 | E8: -0.0426 | G8: =C8 - $M$4 -> 0.013541538 | H8: =G8^2 -> 0.00018337326 | I8: =E8 - $N$4 -> -0.040438462 | J8: =I8^2 -> 0.0016352692 | L8: Coefficient of Variation (CV) | M8: =M7/M4 -> -50.454729 | N8: =N7/N4 -> -16.96823
A9: 46141 | B9: 38.33 | C9: -0.0786 | D9: 55.65 | E9: -0.0149 | G9: =C9 - $M$4 -> -0.077858462 | H9: =G9^2 -> 0.00606194 | I9: =E9 - $N$4 -> -0.012738462 | J9: =I9^2 -> 0.0001622684 | L9: --- VERIFICATION --- | M9: --- | N9: ---
A10: 46140 | B10: 41.6 | C10: -0.0114 | D10: 56.49 | E10: -0.0102 | G10: =C10 - $M$4 -> -0.010658462 | H10: =G10^2 -> 0.0001136028 | I10: =E10 - $N$4 -> -0.0080384615 | J10: =I10^2 -> 6.4616864e-05 | L10: Variance (Excel) | M10: =_xlfn.VAR.S(C3:C67) -> 0.0013998165 | N10: =_xlfn.VAR.S(E3:E67) -> 0.0013452377
A11: 46139 | B11: 42.08 | C11: 0.0094 | D11: 57.07 | E11: -0.013 | G11: =C11 - $M$4 -> 0.010141538 | H11: =G11^2 -> 0.0001028508 | I11: =E11 - $N$4 -> -0.010838462 | J11: =I11^2 -> 0.00011747225 | L11: Standard Deviation (Excel) | M11: =_xlfn.STDEV.S(C3:C67) -> 0.037414122 | N11: =_xlfn.STDEV.S(E3:E67) -> 0.036677482
A12: 46136 | B12: 41.69 | C12: 0.0291 | D12: 57.82 | E12: 0.0091 | G12: =C12 - $M$4 -> 0.029841538 | H12: =G12^2 -> 0.00089051742 | I12: =E12 - $N$4 -> 0.011261538 | J12: =I12^2 -> 0.00012682225
A13: 46135 | B13: 40.51 | C13: 0 | D13: 57.3 | E13: 0.0067 | G13: =C13 - $M$4 -> 0.00074153846 | H13: =G13^2 -> 5.4987929e-07 | I13: =E13 - $N$4 -> 0.0088615385 | J13: =I13^2 -> 7.8526864e-05
A14: 46134 | B14: 40.51 | C14: -0.0309 | D14: 56.92 | E14: -0.0196 | G14: =C14 - $M$4 -> -0.030158462 | H14: =G14^2 -> 0.0009095328 | I14: =E14 - $N$4 -> -0.017438462 | J14: =I14^2 -> 0.00030409994
A15: 46133 | B15: 41.8 | C15: 0.022 | D15: 58.06 | E15: 0.0064 | G15: =C15 - $M$4 -> 0.022741538 | H15: =G15^2 -> 0.00051717757 | I15: =E15 - $N$4 -> 0.0085615385 | J15: =I15^2 -> 7.3299941e-05
A16: 46132 | B16: 40.9 | C16: 0.0012 | D16: 57.69 | E16: -0.0363 | G16: =C16 - $M$4 -> 0.0019415385 | H16: =G16^2 -> 3.7695716e-06 | I16: =E16 - $N$4 -> -0.034138462 | J16: =I16^2 -> 0.0011654346
A17: 46129 | B17: 40.85 | C17: -0.0343 | D17: 59.86 | E17: 0.0022 | G17: =C17 - $M$4 -> -0.033558462 | H17: =G17^2 -> 0.0011261703 | I17: =E17 - $N$4 -> 0.0043615385 | J17: =I17^2 -> 1.9023018e-05
A18: 46128 | B18: 42.3 | C18: 0.0012 | D18: 59.73 | E18: 0.0002 | G18: =C18 - $M$4 -> 0.0019415385 | H18: =G18^2 -> 3.7695716e-06 | I18: =E18 - $N$4 -> 0.0023615385 | J18: =I18^2 -> 5.5768639e-06
A19: 46127 | B19: 42.25 | C19: 0.0074 | D19: 59.72 | E19: 0.03 | G19: =C19 - $M$4 -> 0.0081415385 | H19: =G19^2 -> 6.6284649e-05 | I19: =E19 - $N$4 -> 0.032161538 | J19: =I19^2 -> 0.0010343646
A20: 46126 | B20: 41.94 | C20: 0.0214 | D20: 57.98 | E20: 0.0333 | G20: =C20 - $M$4 -> 0.022141538 | H20: =G20^2 -> 0.00049024773 | I20: =E20 - $N$4 -> 0.035461538 | J20: =I20^2 -> 0.0012575207
A21: 46125 | B21: 41.06 | C21: -0.0561 | D21: 56.11 | E21: -0.069 | G21: =C21 - $M$4 -> -0.055358462 | H21: =G21^2 -> 0.0030645593 | I21: =E21 - $N$4 -> -0.066838462 | J21: =I21^2 -> 0.0044673799
A22: 46122 | B22: 43.5 | C22: -0.0014 | D22: 60.27 | E22: 0.008 | G22: =C22 - $M$4 -> -0.00065846154 | H22: =G22^2 -> 4.335716e-07 | I22: =E22 - $N$4 -> 0.010161538 | J22: =I22^2 -> 0.00010325686
A23: 46121 | B23: 43.56 | C23: 0.0107 | D23: 59.79 | E23: 0.0259 | G23: =C23 - $M$4 -> 0.011441538 | H23: =G23^2 -> 0.0001309088 | I23: =E23 - $N$4 -> 0.028061538 | J23: =I23^2 -> 0.00078744994
... A67: 46055 | B67: 48.53 | C67: 0.0081 | D67: 68.63 | E67: 0.024 | G67: =C67 - $M$4 -> 0.0088415385 | H67: =G67^2 -> 7.8172802e-05 | I67: =E67 - $N$4 -> 0.026161538 | J67: =I67^2 -> 0.00068442609
